Workbook

Sheet Январь
A1: ФИО | B1: Должность | C1: Оклад | D1: Премия | E1: Итого | G1: Должность | H1: Оклад
A2: Иванов Алексей Петрович | B2: =INDEX($G$2:$G$6,RANDBETWEEN(1,5)) -> Бариста | C2: =SUMIF($G$2:$G$6,B2,$H$2:$H$6) -> 35000 | D2: =RANDBETWEEN(1000,10000) -> 2146 | E2: =C2+D2 -> 37146 | G2: Управляющий | H2: 55000
A3: Смирнова Елена Викторовна | B3: =INDEX($G$2:$G$6,RANDBETWEEN(1,5)) -> Уборщик | C3: =SUMIF($G$2:$G$6,B3,$H$2:$H$6) -> 25000 | D3: =RANDBETWEEN(1000,10000) -> 9966 | E3: =C3+D3 -> 34966 | G3: Бариста | H3: 35000
A4: Кузнецов Дмитрий Сергеевич | B4: =INDEX($G$2:$G$6,RANDBETWEEN(1,5)) -> Управляющий | C4: =SUMIF($G$2:$G$6,B4,$H$2:$H$6) -> 55000 | D4: =RANDBETWEEN(1000,10000) -> 1486 | E4: =C4+D4 -> 56486 | G4: Кассир | H4: 30000
A5: Попова Анна Игоревна | B5: =INDEX($G$2:$G$6,RANDBETWEEN(1,5)) -> Бариста | C5: =SUMIF($G$2:$G$6,B5,$H$2:$H$6) -> 35000 | D5: =RANDBETWEEN(1000,10000) -> 9501 | E5: =C5+D5 -> 44501 | G5: Кондитер | H5: 38000
A6: Соколов Максим Андреевич | B6: =INDEX($G$2:$G$6,RANDBETWEEN(1,5)) -> Кондитер | C6: =SUMIF($G$2:$G$6,B6,$H$2:$H$6) -> 38000 | D6: =RANDBETWEEN(1000,10000) -> 2375 | E6: =C6+D6 -> 40375 | G6: Уборщик | H6: 25000
A7: Лебедева Ольга Николаевна | B7: =INDEX($G$2:$G$6,RANDBETWEEN(1,5)) -> Управляющий | C7: =SUMIF($G$2:$G$6,B7,$H$2:$H$6) -> 55000 | D7: =RANDBETWEEN(1000,10000) -> 7154 | E7: =C7+D7 -> 62154
A8: Козлов Артём Романович | B8: =INDEX($G$2:$G$6,RANDBETWEEN(1,5)) -> Кондитер | C8: =SUMIF($G$2:$G$6,B8,$H$2:$H$6) -> 38000 | D8: =RANDBETWEEN(1000,10000) -> 9969 | E8: =C8+D8 -> 47969
A9: Новикова Мария Олеговна | B9: =INDEX($G$2:$G$6,RANDBETWEEN(1,5)) -> Управляющий | C9: =SUMIF($G$2:$G$6,B9,$H$2:$H$6) -> 55000 | D9: =RANDBETWEEN(1000,10000) -> 4026 | E9: =C9+D9 -> 59026
A10: Морозов Илья Денисович | B10: =INDEX($G$2:$G$6,RANDBETWEEN(1,5)) -> Кондитер | C10: =SUMIF($G$2:$G$6,B10,$H$2:$H$6) -> 38000 | D10: =RANDBETWEEN(1000,10000) -> 6527 | E10: =C10+D10 -> 44527
A11: Петрова Татьяна Юрьевна | B11: =INDEX($G$2:$G$6,RANDBETWEEN(1,5)) -> Кассир | C11: =SUMIF($G$2:$G$6,B11,$H$2:$H$6) -> 30000 | D11: =RANDBETWEEN(1000,10000) -> 8733 | E11: =C11+D11 -> 38733
A12: Волков Никита Александрович | B12: =INDEX($G$2:$G$6,RANDBETWEEN(1,5)) -> Управляющий | C12: =SUMIF($G$2:$G$6,B12,$H$2:$H$6) -> 55000 | D12: =RANDBETWEEN(1000,10000) -> 5361 | E12: =C12+D12 -> 60361
A13: Соловьёва Дарья Павловна | B13: =INDEX($G$2:$G$6,RANDBETWEEN(1,5)) -> Бариста | C13: =SUMIF($G$2:$G$6,B13,$H$2:$H$6) -> 35000 | D13: =RANDBETWEEN(1000,10000) -> 8787 | E13: =C13+D13 -> 43787
A14: Васильев Кирилл Евгеньевич | B14: =INDEX($G$2:$G$6,RANDBETWEEN(1,5)) -> Управляющий | C14: =SUMIF($G$2:$G$6,B14,$H$2:$H$6) -> 55000 | D14: =RANDBETWEEN(1000,10000) -> 4733 | E14: =C14+D14 -> 59733
A15: Зайцева Ирина Михайловна | B15: =INDEX($G$2:$G$6,RANDBETWEEN(1,5)) -> Кассир | C15: =SUMIF($G$2:$G$6,B15,$H$2:$H$6) -> 30000 | D15: =RANDBETWEEN(1000,10000) -> 5094 | E15: =C15+D15 -> 35094
A16: Павлов Егор Владимирович | B16: =INDEX($G$2:$G$6,RANDBETWEEN(1,5)) -> Уборщик | C16: =SUMIF($G$2:$G$6,B16,$H$2:$H$6) -> 25000 | D16: =RANDBETWEEN(1000,10000) -> 4016 | E16: =C16+D16 -> 29016
A17: Семёнова Алина Артёмовна | B17: =INDEX($G$2:$G$6,RANDBETWEEN(1,5)) -> Кассир | C17: =SUMIF($G$2:$G$6,B17,$H$2:$H$6) -> 30000 | D17: =RANDBETWEEN(1000,10000) -> 2437 | E17: =C17+D17 -> 32437
A18: Голубев Роман Игоревич | B18: =INDEX($G$2:$G$6,RANDBETWEEN(1,5)) -> Бариста | C18: =SUMIF($G$2:$G$6,B18,$H$2:$H$6) -> 35000 | D18: =RANDBETWEEN(1000,10000) -> 5973 | E18: =C18+D18 -> 40973
... A31: Андреева Вероника Дмитриевна | B31: =INDEX($G$2:$G$6,RANDBETWEEN(1,5)) -> Управляющий | C31: =SUMIF($G$2:$G$6,B31,$H$2:$H$6) -> 55000 | D31: =RANDBETWEEN(1000,10000) -> 8969 | E31: =C31+D31 -> 63969

Sheet Февраль
A1: ФИО | B1: Должность | C1: Оклад | D1: Премия | E1: Итого
A2: =Январь!$A$2 -> Иванов Алексей Петрович | B2: =Январь!$B$2 -> Бариста | C2: =Январь!$C$2+RANDBETWEEN(-5000,5000) -> 35967 | D2: =RANDBETWEEN(1000,10000) -> 1170 | E2: =C2+D2 -> 37137
A3: =Январь!$A$3 -> Смирнова Елена Викторовна | B3: =Январь!$B$3 -> Уборщик | C3: =Январь!$C$3+RANDBETWEEN(-5000,5000) -> 21807 | D3: =RANDBETWEEN(1000,10000) -> 9220 | E3: =C3+D3 -> 31027
A4: =Январь!$A$4 -> Кузнецов Дмитрий Сергеевич | B4: =Январь!$B$4 -> Управляющий | C4: =Январь!$C$4+RANDBETWEEN(-5000,5000) -> 56364 | D4: =RANDBETWEEN(1000,10000) -> 4173 | E4: =C4+D4 -> 60537
A5: =Январь!$A$5 -> Попова Анна Игоревна | B5: =Январь!$B$5 -> Бариста | C5: =Январь!$C$5+RANDBETWEEN(-5000,5000) -> 36553 | D5: =RANDBETWEEN(1000,10000) -> 4475 | E5: =C5+D5 -> 41028
A6: =Январь!$A$6 -> Соколов Максим Андреевич | B6: =Январь!$B$6 -> Кондитер | C6: =Январь!$C$6+RANDBETWEEN(-5000,5000) -> 33834 | D6: =RANDBETWEEN(1000,10000) -> 2440 | E6: =C6+D6 -> 36274
A7: =Январь!$A$7 -> Лебедева Ольга Николаевна | B7: =Январь!$B$7 -> Управляющий | C7: =Январь!$C$7+RANDBETWEEN(-5000,5000) -> 58936 | D7: =RANDBETWEEN(1000,10000) -> 8773 | E7: =C7+D7 -> 67709
A8: =Январь!$A$8 -> Козлов Артём Романович | B8: =Январь!$B$8 -> Кондитер | C8: =Январь!$C$8+RANDBETWEEN(-5000,5000) -> 39941 | D8: =RANDBETWEEN(1000,10000) -> 5814 | E8: =C8+D8 -> 45755
A9: =Январь!$A$9 -> Новикова Мария Олеговна | B9: =Январь!$B$9 -> Управляющий | C9: =Январь!$C$9+RANDBETWEEN(-5000,5000) -> 58007 | D9: =RANDBETWEEN(1000,10000) -> 1644 | E9: =C9+D9 -> 59651
A10: =Январь!$A$10 -> Морозов Илья Денисович | B10: =Январь!$B$10 -> Кондитер | C10: =Январь!$C$10+RANDBETWEEN(-5000,5000) -> 33822 | D10: =RANDBETWEEN(1000,10000) -> 4469 | E10: =C10+D10 -> 38291
A11: =Январь!$A$11 -> Петрова Татьяна Юрьевна | B11: =Январь!$B$11 -> Кассир | C11: =Январь!$C$11+RANDBETWEEN(-5000,5000) -> 27531 | D11: =RANDBETWEEN(1000,10000) -> 6030 | E11: =C11+D11 -> 33561
A12: =Январь!$A$12 -> Волков Никита Александрович | B12: =Январь!$B$12 -> Управляющий | C12: =Январь!$C$12+RANDBETWEEN(-5000,5000) -> 57130 | D12: =RANDBETWEEN(1000,10000) -> 4635 | E12: =C12+D12 -> 61765
A13: =Январь!$A$13 -> Соловьёва Дарья Павловна | B13: =Январь!$B$13 -> Бариста | C13: =Январь!$C$13+RANDBETWEEN(-5000,5000) -> 35520 | D13: =RANDBETWEEN(1000,10000) -> 7162 | E13: =C13+D13 -> 42682
A14: =Январь!$A$14 -> Васильев Кирилл Евгеньевич | B14: =Январь!$B$14 -> Управляющий | C14: =Январь!$C$14+RANDBETWEEN(-5000,5000) -> 57955 | D14: =RANDBETWEEN(1000,10000) -> 7082 | E14: =C14+D14 -> 65037
A15: =Январь!$A$15 -> Зайцева Ирина Михайловна | B15: =Январь!$B$15 -> Кассир | C15: =Январь!$C$15+RANDBETWEEN(-5000,5000) -> 31210 | D15: =RANDBETWEEN(1000,10000) -> 1123 | E15: =C15+D15 -> 32333
A16: =Январь!$A$16 -> Павлов Егор Владимирович | B16: =Январь!$B$16 -> Уборщик | C16: =Январь!$C$16+RANDBETWEEN(-5000,5000) -> 22058 | D16: =RANDBETWEEN(1000,10000) -> 8067 | E16: =C16+D16 -> 30125
A17: =Январь!$A$17 -> Семёнова Алина Артёмовна | B17: =Январь!$B$17 -> Кассир | C17: =Январь!$C$17+RANDBETWEEN(-5000,5000) -> 31557 | D17: =RANDBETWEEN(1000,10000) -> 5813 | E17: =C17+D17 -> 37370
A18: =Январь!$A$18 -> Голубев Роман Игоревич | B18: =Январь!$B$18 -> Бариста | C18: =Январь!$C$18+RANDBETWEEN(-5000,5000) -> 39629 | D18: =RANDBETWEEN(1000,10000) -> 1851 | E18: =C18+D18 -> 41480
A19: =Январь!$A$19 -> Виноградова Юлия Сергеевна | B19: =Январь!$B$19 -> Управляющий | C19: =Январь!$C$19+RANDBETWEEN(-5000,5000) -> 52949 | D19: =RANDBETWEEN(1000,10000) -> 6282 | E19: =C19+D19 -> 59231
A20: =Январь!$A$20 -> Богданов Станислав Олегович | B20: =Январь!$B$20 -> Бариста | C20: =Январь!$C$20+RANDBETWEEN(-5000,5000) -> 36043 | D20: =RANDBETWEEN(1000,10000) -> 6348 | E20: =C20+D20 -> 42391
A21: =Январь!$A$21 -> Воробьёва Екатерина Андреевна | B21: =Январь!$B$21 -> Кондитер | C21: =Январь!$C$21+RANDBETWEEN(-5000,5000) -> 35903 | D21: =RANDBETWEEN(1000,10000) -> 3197 | E21: =C21+D21 -> 39100
A22: =Январь!$A$22 -> Фёдоров Павел Дмитриевич | B22: =Январь!$B$22 -> Кондитер | C22: =Январь!$C$22+RANDBETWEEN(-5000,5000) -> 42912 | D22: =RANDBETWEEN(1000,10000) -> 2820 | E22: =C22+D22 -> 45732
A23: =Январь!$A$23 -> Михайлова Светлана Ивановна | B23: =Январь!$B$23 -> Кассир | C23: =Январь!$C$23+RANDBETWEEN(-5000,5000) -> 32220 | D23: =RANDBETWEEN(1000,10000) -> 4083 | E23: =C23+D23 -> 36303
A24: =Январь!$A$24 -> Беляев Антон Николаевич | B24: =Январь!$B$24 -> Управляющий | C24: =Январь!$C$24+RANDBETWEEN(-5000,5000) -> 59175 | D24: =RANDBETWEEN(1000,10000) -> 5599 | E24: =C24+D24 -> 64774
A25: =Январь!$A$25 -> Тарасова Валерия Романовна | B25: =Январь!$B$25 -> Кондитер | C25: =Январь!$C$25+RANDBETWEEN(-5000,5000) -> 35259 | D25: =RANDBETWEEN(1000,10000) -> 8029 | E25: =C25+D25 -> 43288
A26: =Январь!$A$26 -> Белов Глеб Максимович | B26: =Январь!$B$26 -> Бариста | C26: =Январь!$C$26+RANDBETWEEN(-5000,5000) -> 32989 | D26: =RANDBETWEEN(1000,10000) -> 5196 | E26: =C26+D26 -> 38185
A27: =Январь!$A$27 -> Комарова Полина Алексеевна | B27: =Январь!$B$27 -> Кассир | C27: =Январь!$C$27+RANDBETWEEN(-5000,5000) -> 31509 | D27: =RANDBETWEEN(1000,10000) -> 9775 | E27: =C27+D27 -> 41284
A28: =Январь!$A$28 -> Орлов Владислав Станиславович | B28: =Январь!$B$28 -> Управляющий | C28: =Январь!$C$28+RANDBETWEEN(-5000,5000) -> 56311 | D28: =RANDBETWEEN(1000,10000) -> 3146 | E28: =C28+D28 -> 59457
A29: =Январь!$A$29 -> Киселёва Надежда Петровна | B29: =Январь!$B$29 -> Уборщик | C29: =Январь!$C$29+RANDBETWEEN(-5000,5000) -> 28670 | D29: =RANDBETWEEN(1000,10000) -> 5767 | E29: =C29+D29 -> 34437
A30: =Январь!$A$30 -> Макаров Тимур Русланович | B30: =Январь!$B$30 -> Кассир | C30: =Январь!$C$30+RANDBETWEEN(-5000,5000) -> 34061 | D30: =RANDBETWEEN(1000,10000) -> 6272 | E30: =C30+D30 -> 40333
A31: =Январь!$A$31 -> Андреева Вероника Дмитриевна | B31: =Январь!$B$31 -> Управляющий | C31: =Январь!$C$31+RANDBETWEEN(-5000,5000) -> 52993 | D31: =RANDBETWEEN(1000,10000) -> 2384 | E31: =C31+D31 -> 55377

Sheet Март
A1: ФИО | B1: Должность | C1: Оклад | D1: Премия | E1: Итого
A2: =Январь!$A$2 -> Иванов Алексей Петрович | B2: =Январь!$B$2 -> Бариста | C2: =Январь!$C$2+RANDBETWEEN(-5000,5000) -> 33234 | D2: =RANDBETWEEN(1000,10000) -> 5121 | E2: =C2+D2 -> 38355
A3: =Январь!$A$3 -> Смирнова Елена Викторовна | B3: =Январь!$B$3 -> Уборщик | C3: =Январь!$C$3+RANDBETWEEN(-5000,5000) -> 24729 | D3: =RANDBETWEEN(1000,10000) -> 6361 | E3: =C3+D3 -> 31090
A4: =Январь!$A$4 -> Кузнецов Дмитрий Сергеевич | B4: =Январь!$B$4 -> Управляющий | C4: =Январь!$C$4+RANDBETWEEN(-5000,5000) -> 58656 | D4: =RANDBETWEEN(1000,10000) -> 9333 | E4: =C4+D4 -> 67989
A5: =Январь!$A$5 -> Попова Анна Игоревна | B5: =Январь!$B$5 -> Бариста | C5: =Январь!$C$5+RANDBETWEEN(-5000,5000) -> 39867 | D5: =RANDBETWEEN(1000,10000) -> 6107 | E5: =C5+D5 -> 45974
A6: =Январь!$A$6 -> Соколов Максим Андреевич | B6: =Январь!$B$6 -> Кондитер | C6: =Январь!$C$6+RANDBETWEEN(-5000,5000) -> 34149 | D6: =RANDBETWEEN(1000,10000) -> 5641 | E6: =C6+D6 -> 39790
A7: =Январь!$A$7 -> Лебедева Ольга Николаевна | B7: =Январь!$B$7 -> Управляющий | C7: =Январь!$C$7+RANDBETWEEN(-5000,5000) -> 55940 | D7: =RANDBETWEEN(1000,10000) -> 8153 | E7: =C7+D7 -> 64093
A8: =Январь!$A$8 -> Козлов Артём Романович | B8: =Январь!$B$8 -> Кондитер | C8: =Январь!$C$8+RANDBETWEEN(-5000,5000) -> 42960 | D8: =RANDBETWEEN(1000,10000) -> 2262 | E8: =C8+D8 -> 45222
A9: =Январь!$A$9 -> Новикова Мария Олеговна | B9: =Январь!$B$9 -> Управляющий | C9: =Январь!$C$9+RANDBETWEEN(-5000,5000) -> 53658 | D9: =RANDBETWEEN(1000,10000) -> 1195 | E9: =C9+D9 -> 54853
A10: =Январь!$A$10 -> Морозов Илья Денисович | B10: =Январь!$B$10 -> Кондитер | C10: =Январь!$C$10+RANDBETWEEN(-5000,5000) -> 35950 | D10: =RANDBETWEEN(1000,10000) -> 9453 | E10: =C10+D10 -> 45403
A11: =Январь!$A$11 -> Петрова Татьяна Юрьевна | B11: =Январь!$B$11 -> Кассир | C11: =Январь!$C$11+RANDBETWEEN(-5000,5000) -> 25723 | D11: =RANDBETWEEN(1000,10000) -> 1736 | E11: =C11+D11 -> 27459
A12: =Январь!$A$12 -> Волков Никита Александрович | B12: =Январь!$B$12 -> Управляющий | C12: =Январь!$C$12+RANDBETWEEN(-5000,5000) -> 56395 | D12: =RANDBETWEEN(1000,10000) -> 5613 | E12: =C12+D12 -> 62008
A13: =Январь!$A$13 -> Соловьёва Дарья Павловна | B13: =Январь!$B$13 -> Бариста | C13: =Январь!$C$13+RANDBETWEEN(-5000,5000) -> 37562 | D13: =RANDBETWEEN(1000,10000) -> 7878 | E13: =C13+D13 -> 45440
A14: =Январь!$A$14 -> Васильев Кирилл Евгеньевич | B14: =Январь!$B$14 -> Управляющий | C14: =Январь!$C$14+RANDBETWEEN(-5000,5000) -> 50839 | D14: =RANDBETWEEN(1000,10000) -> 4894 | E14: =C14+D14 -> 55733
A15: =Январь!$A$15 -> Зайцева Ирина Михайловна | B15: =Январь!$B$15 -> Кассир | C15: =Январь!$C$15+RANDBETWEEN(-5000,5000) -> 29495 | D15: =RANDBETWEEN(1000,10000) -> 5185 | E15: =C15+D15 -> 34680
A16: =Январь!$A$16 -> Павлов Егор Владимирович | B16: =Январь!$B$16 -> Уборщик | C16: =Январь!$C$16+RANDBETWEEN(-5000,5000) -> 26016 | D16: =RANDBETWEEN(1000,10000) -> 2487 | E16: =C16+D16 -> 28503
A17: =Январь!$A$17 -> Семёнова Алина Артёмовна | B17: =Январь!$B$17 -> Кассир | C17: =Январь!$C$17+RANDBETWEEN(-5000,5000) -> 32631 | D17: =RANDBETWEEN(1000,10000) -> 1423 | E17: =C17+D17 -> 34054
A18: =Январь!$A$18 -> Голубев Роман Игоревич | B18: =Январь!$B$18 -> Бариста | C18: =Январь!$C$18+RANDBETWEEN(-5000,5000) -> 30627 | D18: =RANDBETWEEN(1000,10000) -> 3400 | E18: =C18+D18 -> 34027
A19: =Январь!$A$19 -> Виноградова Юлия Сергеевна | B19: =Январь!$B$19 -> Управляющий | C19: =Январь!$C$19+RANDBETWEEN(-5000,5000) -> 51896 | D19: =RANDBETWEEN(1000,10000) -> 2621 | E19: =C19+D19 -> 54517
A20: =Январь!$A$20 -> Богданов Станислав Олегович | B20: =Январь!$B$20 -> Бариста | C20: =Январь!$C$20+RANDBETWEEN(-5000,5000) -> 37935 | D20: =RANDBETWEEN(1000,10000) -> 9581 | E20: =C20+D20 -> 47516
A21: =Январь!$A$21 -> Воробьёва Екатерина Андреевна | B21: =Январь!$B$21 -> Кондитер | C21: =Январь!$C$21+RANDBETWEEN(-5000,5000) -> 40826 | D21: =RANDBETWEEN(1000,10000) -> 2095 | E21: =C21+D21 -> 42921
A22: =Январь!$A$22 -> Фёдоров Павел Дмитриевич | B22: =Январь!$B$22 -> Кондитер | C22: =Январь!$C$22+RANDBETWEEN(-5000,5000) -> 38557 | D22: =RANDBETWEEN(1000,10000) -> 3419 | E22: =C22+D22 -> 41976
A23: =Январь!$A$23 -> Михайлова Светлана Ивановна | B23: =Январь!$B$23 -> Кассир | C23: =Январь!$C$23+RANDBETWEEN(-5000,5000) -> 30943 | D23: =RANDBETWEEN(1000,10000) -> 8963 | E23: =C23+D23 -> 39906
A24: =Январь!$A$24 -> Беляев Антон Николаевич | B24: =Январь!$B$24 -> Управляющий | C24: =Январь!$C$24+RANDBETWEEN(-5000,5000) -> 51605 | D24: =RANDBETWEEN(1000,10000) -> 2162 | E24: =C24+D24 -> 53767
A25: =Январь!$A$25 -> Тарасова Валерия Романовна | B25: =Январь!$B$25 -> Кондитер | C25: =Январь!$C$25+RANDBETWEEN(-5000,5000) -> 35827 | D25: =RANDBETWEEN(1000,10000) -> 9125 | E25: =C25+D25 -> 44952
A26: =Январь!$A$26 -> Белов Глеб Максимович | B26: =Январь!$B$26 -> Бариста | C26: =Январь!$C$26+RANDBETWEEN(-5000,5000) -> 30190 | D26: =RANDBETWEEN(1000,10000) -> 1416 | E26: =C26+D26 -> 31606
A27: =Январь!$A$27 -> Комарова Полина Алексеевна | B27: =Январь!$B$27 -> Кассир | C27: =Январь!$C$27+RANDBETWEEN(-5000,5000) -> 29890 | D27: =RANDBETWEEN(1000,10000) -> 5211 | E27: =C27+D27 -> 35101
A28: =Январь!$A$28 -> Орлов Владислав Станиславович | B28: =Январь!$B$28 -> Управляющий | C28: =Январь!$C$28+RANDBETWEEN(-5000,5000) -> 56999 | D28: =RANDBETWEEN(1000,10000) -> 2658 | E28: =C28+D28 -> 59657
A29: =Январь!$A$29 -> Киселёва Надежда Петровна | B29: =Январь!$B$29 -> Уборщик | C29: =Январь!$C$29+RANDBETWEEN(-5000,5000) -> 23896 | D29: =RANDBETWEEN(1000,10000) -> 6267 | E29: =C29+D29 -> 30163
A30: =Январь!$A$30 -> Макаров Тимур Русланович | B30: =Январь!$B$30 -> Кассир | C30: =Январь!$C$30+RANDBETWEEN(-5000,5000) -> 34156 | D30: =RANDBETWEEN(1000,10000) -> 6794 | E30: =C30+D30 -> 40950
A31: =Январь!$A$31 -> Андреева Вероника Дмитриевна | B31: =Январь!$B$31 -> Управляющий | C31: =Январь!$C$31+RANDBETWEEN(-5000,5000) -> 51293 | D31: =RANDBETWEEN(1000,10000) -> 1374 | E31: =C31+D31 -> 52667

Sheet Апрель
A1: ФИО | B1: Должность | C1: Оклад | D1: Премия | E1: Итого
A2: =Январь!$A$2 -> Иванов Алексей Петрович | B2: =Январь!$B$2 -> Бариста | C2: =Январь!$C$2+RANDBETWEEN(-5000,5000) -> 35296 | D2: =RANDBETWEEN(1000,10000) -> 5831 | E2: =C2+D2 -> 41127
A3: =Январь!$A$3 -> Смирнова Елена Викторовна | B3: =Январь!$B$3 -> Уборщик | C3: =Январь!$C$3+RANDBETWEEN(-5000,5000) -> 20775 | D3: =RANDBETWEEN(1000,10000) -> 3122 | E3: =C3+D3 -> 23897
A4: =Январь!$A$4 -> Кузнецов Дмитрий Сергеевич | B4: =Январь!$B$4 -> Управляющий | C4: =Январь!$C$4+RANDBETWEEN(-5000,5000) -> 52638 | D4: =RANDBETWEEN(1000,10000) -> 2955 | E4: =C4+D4 -> 55593
A5: =Январь!$A$5 -> Попова Анна Игоревна | B5: =Январь!$B$5 -> Бариста | C5: =Январь!$C$5+RANDBETWEEN(-5000,5000) -> 33384 | D5: =RANDBETWEEN(1000,10000) -> 5697 | E5: =C5+D5 -> 39081
A6: =Январь!$A$6 -> Соколов Максим Андреевич | B6: =Январь!$B$6 -> Кондитер | C6: =Январь!$C$6+RANDBETWEEN(-5000,5000) -> 36582 | D6: =RANDBETWEEN(1000,10000) -> 4851 | E6: =C6+D6 -> 41433
A7: =Январь!$A$7 -> Лебедева Ольга Николаевна | B7: =Январь!$B$7 -> Управляющий | C7: =Январь!$C$7+RANDBETWEEN(-5000,5000) -> 59017 | D7: =RANDBETWEEN(1000,10000) -> 8411 | E7: =C7+D7 -> 67428
A8: =Январь!$A$8 -> Козлов Артём Романович | B8: =Январь!$B$8 -> Кондитер | C8: =Январь!$C$8+RANDBETWEEN(-5000,5000) -> 40081 | D8: =RANDBETWEEN(1000,10000) -> 4747 | E8: =C8+D8 -> 44828
A9: =Январь!$A$9 -> Новикова Мария Олеговна | B9: =Январь!$B$9 -> Управляющий | C9: =Январь!$C$9+RANDBETWEEN(-5000,5000) -> 59199 | D9: =RANDBETWEEN(1000,10000) -> 1908 | E9: =C9+D9 -> 61107
A10: =Январь!$A$10 -> Морозов Илья Денисович | B10: =Январь!$B$10 -> Кондитер | C10: =Январь!$C$10+RANDBETWEEN(-5000,5000) -> 35048 | D10: =RANDBETWEEN(1000,10000) -> 3734 | E10: =C10+D10 -> 38782
A11: =Январь!$A$11 -> Петрова Татьяна Юрьевна | B11: =Январь!$B$11 -> Кассир | C11: =Январь!$C$11+RANDBETWEEN(-5000,5000) -> 30478 | D11: =RANDBETWEEN(1000,10000) -> 2333 | E11: =C11+D11 -> 32811
A12: =Январь!$A$12 -> Волков Никита Александрович | B12: =Январь!$B$12 -> Управляющий | C12: =Январь!$C$12+RANDBETWEEN(-5000,5000) -> 58152 | D12: =RANDBETWEEN(1000,10000) -> 9836 | E12: =C12+D12 -> 67988
A13: =Январь!$A$13 -> Соловьёва Дарья Павловна | B13: =Январь!$B$13 -> Бариста | C13: =Январь!$C$13+RANDBETWEEN(-5000,5000) -> 32195 | D13: =RANDBETWEEN(1000,10000) -> 8691 | E13: =C13+D13 -> 40886
A14: =Январь!$A$14 -> Васильев Кирилл Евгеньевич | B14: =Январь!$B$14 -> Управляющий | C14: =Январь!$C$14+RANDBETWEEN(-5000,5000) -> 54186 | D14: =RANDBETWEEN(1000,10000) -> 9202 | E14: =C14+D14 -> 63388
A15: =Январь!$A$15 -> Зайцева Ирина Михайловна | B15: =Январь!$B$15 -> Кассир | C15: =Январь!$C$15+RANDBETWEEN(-5000,5000) -> 31985 | D15: =RANDBETWEEN(1000,10000) -> 9100 | E15: =C15+D15 -> 41085
A16: =Январь!$A$16 -> Павлов Егор Владимирович | B16: =Январь!$B$16 -> Уборщик | C16: =Январь!$C$16+RANDBETWEEN(-5000,5000) -> 20322 | D16: =RANDBETWEEN(1000,10000) -> 3531 | E16: =C16+D16 -> 23853
A17: =Январь!$A$17 -> Семёнова Алина Артёмовна | B17: =Январь!$B$17 -> Кассир | C17: =Январь!$C$17+RANDBETWEEN(-5000,5000) -> 33241 | D17: =RANDBETWEEN(1000,10000) -> 5406 | E17: =C17+D17 -> 38647
A18: =Январь!$A$18 -> Голубев Роман Игоревич | B18: =Январь!$B$18 -> Бариста | C18: =Январь!$C$18+RANDBETWEEN(-5000,5000) -> 31669 | D18: =RANDBETWEEN(1000,10000) -> 6764 | E18: =C18+D18 -> 38433
A19: =Январь!$A$19 -> Виноградова Юлия Сергеевна | B19: =Январь!$B$19 -> Управляющий | C19: =Январь!$C$19+RANDBETWEEN(-5000,5000) -> 59133 | D19: =RANDBETWEEN(1000,10000) -> 5075 | E19: =C19+D19 -> 64208
A20: =Январь!$A$20 -> Богданов Станислав Олегович | B20: =Январь!$B$20 -> Бариста | C20: =Январь!$C$20+RANDBETWEEN(-5000,5000) -> 39455 | D20: =RANDBETWEEN(1000,10000) -> 5764 | E20: =C20+D20 -> 45219
A21: =Январь!$A$21 -> Воробьёва Екатерина Андреевна | B21: =Январь!$B$21 -> Кондитер | C21: =Январь!$C$21+RANDBETWEEN(-5000,5000) -> 39084 | D21: =RANDBETWEEN(1000,10000) -> 3696 | E21: =C21+D21 -> 42780
A22: =Январь!$A$22 -> Фёдоров Павел Дмитриевич | B22: =Январь!$B$22 -> Кондитер | C22: =Январь!$C$22+RANDBETWEEN(-5000,5000) -> 33098 | D22: =RANDBETWEEN(1000,10000) -> 1981 | E22: =C22+D22 -> 35079
A23: =Январь!$A$23 -> Михайлова Светлана Ивановна | B23: =Январь!$B$23 -> Кассир | C23: =Январь!$C$23+RANDBETWEEN(-5000,5000) -> 25672 | D23: =RANDBETWEEN(1000,10000) -> 3096 | E23: =C23+D23 -> 28768
A24: =Январь!$A$24 -> Беляев Антон Николаевич | B24: =Январь!$B$24 -> Управляющий | C24: =Январь!$C$24+RANDBETWEEN(-5000,5000) -> 57906 | D24: =RANDBETWEEN(1000,10000) -> 9624 | E24: =C24+D24 -> 67530
A25: =Январь!$A$25 -> Тарасова Валерия Романовна | B25: =Январь!$B$25 -> Кондитер | C25: =Январь!$C$25+RANDBETWEEN(-5000,5000) -> 33032 | D25: =RANDBETWEEN(1000,10000) -> 1646 | E25: =C25+D25 -> 34678
A26: =Январь!$A$26 -> Белов Глеб Максимович | B26: =Январь!$B$26 -> Бариста | C26: =Январь!$C$26+RANDBETWEEN(-5000,5000) -> 30023 | D26: =RANDBETWEEN(1000,10000) -> 3475 | E26: =C26+D26 -> 33498
A27: =Январь!$A$27 -> Комарова Полина Алексеевна | B27: =Январь!$B$27 -> Кассир | C27: =Январь!$C$27+RANDBETWEEN(-5000,5000) -> 32176 | D27: =RANDBETWEEN(1000,10000) -> 2130 | E27: =C27+D27 -> 34306
A28: =Январь!$A$28 -> Орлов Владислав Станиславович | B28: =Январь!$B$28 -> Управляющий | C28: =Январь!$C$28+RANDBETWEEN(-5000,5000) -> 57790 | D28: =RANDBETWEEN(1000,10000) -> 4476 | E28: =C28+D28 -> 62266
A29: =Январь!$A$29 -> Киселёва Надежда Петровна | B29: =Январь!$B$29 -> Уборщик | C29: =Январь!$C$29+RANDBETWEEN(-5000,5000) -> 27624 | D29: =RANDBETWEEN(1000,10000) -> 5551 | E29: =C29+D29 -> 33175
A30: =Январь!$A$30 -> Макаров Тимур Русланович | B30: =Январь!$B$30 -> Кассир | C30: =Январь!$C$30+RANDBETWEEN(-5000,5000) -> 33072 | D30: =RANDBETWEEN(1000,10000) -> 4622 | E30: =C30+D30 -> 37694
A31: =Январь!$A$31 -> Андреева Вероника Дмитриевна | B31: =Январь!$B$31 -> Управляющий | C31: =Январь!$C$31+RANDBETWEEN(-5000,5000) -> 51528 | D31: =RANDBETWEEN(1000,10000) -> 8390 | E31: =C31+D31 -> 59918

Sheet Май
A1: ФИО | B1: Должность | C1: Оклад | D1: Премия | E1: Итого
A2: =Январь!$A$2 -> Иванов Алексей Петрович | B2: =Январь!$B$2 -> Бариста | C2: =Январь!$C$2+RANDBETWEEN(-5000,5000) -> 36405 | D2: =RANDBETWEEN(1000,10000) -> 7209 | E2: =C2+D2 -> 43614
A3: =Январь!$A$3 -> Смирнова Елена Викторовна | B3: =Январь!$B$3 -> Уборщик | C3: =Январь!$C$3+RANDBETWEEN(-5000,5000) -> 25528 | D3: =RANDBETWEEN(1000,10000) -> 4753 | E3: =C3+D3 -> 30281
A4: =Январь!$A$4 -> Кузнецов Дмитрий Сергеевич | B4: =Январь!$B$4 -> Управляющий | C4: =Январь!$C$4+RANDBETWEEN(-5000,5000) -> 54693 | D4: =RANDBETWEEN(1000,10000) -> 3272 | E4: =C4+D4 -> 57965
A5: =Январь!$A$5 -> Попова Анна Игоревна | B5: =Январь!$B$5 -> Бариста | C5: =Январь!$C$5+RANDBETWEEN(-5000,5000) -> 36627 | D5: =RANDBETWEEN(1000,10000) -> 8028 | E5: =C5+D5 -> 44655
A6: =Январь!$A$6 -> Соколов Максим Андреевич | B6: =Январь!$B$6 -> Кондитер | C6: =Январь!$C$6+RANDBETWEEN(-5000,5000) -> 33379 | D6: =RANDBETWEEN(1000,10000) -> 8488 | E6: =C6+D6 -> 41867
A7: =Январь!$A$7 -> Лебедева Ольга Николаевна | B7: =Январь!$B$7 -> Управляющий | C7: =Январь!$C$7+RANDBETWEEN(-5000,5000) -> 58621 | D7: =RANDBETWEEN(1000,10000) -> 5165 | E7: =C7+D7 -> 63786
A8: =Январь!$A$8 -> Козлов Артём Романович | B8: =Январь!$B$8 -> Кондитер | C8: =Январь!$C$8+RANDBETWEEN(-5000,5000) -> 37435 | D8: =RANDBETWEEN(1000,10000) -> 5919 | E8: =C8+D8 -> 43354
A9: =Январь!$A$9 -> Новикова Мария Олеговна | B9: =Январь!$B$9 -> Управляющий | C9: =Январь!$C$9+RANDBETWEEN(-5000,5000) -> 59429 | D9: =RANDBETWEEN(1000,10000) -> 1566 | E9: =C9+D9 -> 60995
A10: =Январь!$A$10 -> Морозов Илья Денисович | B10: =Январь!$B$10 -> Кондитер | C10: =Январь!$C$10+RANDBETWEEN(-5000,5000) -> 33207 | D10: =RANDBETWEEN(1000,10000) -> 5368 | E10: =C10+D10 -> 38575
A11: =Январь!$A$11 -> Петрова Татьяна Юрьевна | B11: =Январь!$B$11 -> Кассир | C11: =Январь!$C$11+RANDBETWEEN(-5000,5000) -> 27387 | D11: =RANDBETWEEN(1000,10000) -> 4329 | E11: =C11+D11 -> 31716
A12: =Январь!$A$12 -> Волков Никита Александрович | B12: =Январь!$B$12 -> Управляющий | C12: =Январь!$C$12+RANDBETWEEN(-5000,5000) -> 54027 | D12: =RANDBETWEEN(1000,10000) -> 4236 | E12: =C12+D12 -> 58263
A13: =Январь!$A$13 -> Соловьёва Дарья Павловна | B13: =Январь!$B$13 -> Бариста | C13: =Январь!$C$13+RANDBETWEEN(-5000,5000) -> 34908 | D13: =RANDBETWEEN(1000,10000) -> 2795 | E13: =C13+D13 -> 37703
A14: =Январь!$A$14 -> Васильев Кирилл Евгеньевич | B14: =Январь!$B$14 -> Управляющий | C14: =Январь!$C$14+RANDBETWEEN(-5000,5000) -> 52422 | D14: =RANDBETWEEN(1000,10000) -> 8283 | E14: =C14+D14 -> 60705
A15: =Январь!$A$15 -> Зайцева Ирина Михайловна | B15: =Январь!$B$15 -> Кассир | C15: =Январь!$C$15+RANDBETWEEN(-5000,5000) -> 27871 | D15: =RANDBETWEEN(1000,10000) -> 5830 | E15: =C15+D15 -> 33701
A16: =Январь!$A$16 -> Павлов Егор Владимирович | B16: =Январь!$B$16 -> Уборщик | C16: =Январь!$C$16+RANDBETWEEN(-5000,5000) -> 25877 | D16: =RANDBETWEEN(1000,10000) -> 4526 | E16: =C16+D16 -> 30403
A17: =Январь!$A$17 -> Семёнова Алина Артёмовна | B17: =Январь!$B$17 -> Кассир | C17: =Январь!$C$17+RANDBETWEEN(-5000,5000) -> 31495 | D17: =RANDBETWEEN(1000,10000) -> 5933 | E17: =C17+D17 -> 37428
A18: =Январь!$A$18 -> Голубев Роман Игоревич | B18: =Январь!$B$18 -> Бариста | C18: =Январь!$C$18+RANDBETWEEN(-5000,5000) -> 32879 | D18: =RANDBETWEEN(1000,10000) -> 6008 | E18: =C18+D18 -> 38887
A19: =Январь!$A$19 -> Виноградова Юлия Сергеевна | B19: =Январь!$B$19 -> Управляющий | C19: =Январь!$C$19+RANDBETWEEN(-5000,5000) -> 57084 | D19: =RANDBETWEEN(1000,10000) -> 2803 | E19: =C19+D19 -> 59887
A20: =Январь!$A$20 -> Богданов Станислав Олегович | B20: =Январь!$B$20 -> Бариста | C20: =Январь!$C$20+RANDBETWEEN(-5000,5000) -> 34776 | D20: =RANDBETWEEN(1000,10000) -> 9361 | E20: =C20+D20 -> 44137
A21: =Январь!$A$21 -> Воробьёва Екатерина Андреевна | B21: =Январь!$B$21 -> Кондитер | C21: =Январь!$C$21+RANDBETWEEN(-5000,5000) -> 35730 | D21: =RANDBETWEEN(1000,10000) -> 9539 | E21: =C21+D21 -> 45269
A22: =Январь!$A$22 -> Фёдоров Павел Дмитриевич | B22: =Январь!$B$22 -> Кондитер | C22: =Январь!$C$22+RANDBETWEEN(-5000,5000) -> 35356 | D22: =RANDBETWEEN(1000,10000) -> 1062 | E22: =C22+D22 -> 36418
A23: =Январь!$A$23 -> Михайлова Светлана Ивановна | B23: =Январь!$B$23 -> Кассир | C23: =Январь!$C$23+RANDBETWEEN(-5000,5000) -> 31675 | D23: =RANDBETWEEN(1000,10000) -> 8956 | E23: =C23+D23 -> 40631
A24: =Январь!$A$24 -> Беляев Антон Николаевич | B24: =Январь!$B$24 -> Управляющий | C24: =Январь!$C$24+RANDBETWEEN(-5000,5000) -> 58620 | D24: =RANDBETWEEN(1000,10000) -> 8525 | E24: =C24+D24 -> 67145
A25: =Январь!$A$25 -> Тарасова Валерия Романовна | B25: =Январь!$B$25 -> Кондитер | C25: =Январь!$C$25+RANDBETWEEN(-5000,5000) -> 41355 | D25: =RANDBETWEEN(1000,10000) -> 9567 | E25: =C25+D25 -> 50922
A26: =Январь!$A$26 -> Белов Глеб Максимович | B26: =Январь!$B$26 -> Бариста | C26: =Январь!$C$26+RANDBETWEEN(-5000,5000) -> 33050 | D26: =RANDBETWEEN(1000,10000) -> 3488 | E26: =C26+D26 -> 36538
A27: =Январь!$A$27 -> Комарова Полина Алексеевна | B27: =Январь!$B$27 -> Кассир | C27: =Январь!$C$27+RANDBETWEEN(-5000,5000) -> 28334 | D27: =RANDBETWEEN(1000,10000) -> 9254 | E27: =C27+D27 -> 37588
A28: =Январь!$A$28 -> Орлов Владислав Станиславович | B28: =Январь!$B$28 -> Управляющий | C28: =Январь!$C$28+RANDBETWEEN(-5000,5000) -> 57318 | D28: =RANDBETWEEN(1000,10000) -> 4810 | E28: =C28+D28 -> 62128
A29: =Январь!$A$29 -> Киселёва Надежда Петровна | B29: =Январь!$B$29 -> Уборщик | C29: =Январь!$C$29+RANDBETWEEN(-5000,5000) -> 26389 | D29: =RANDBETWEEN(1000,10000) -> 9378 | E29: =C29+D29 -> 35767
A30: =Январь!$A$30 -> Макаров Тимур Русланович | B30: =Январь!$B$30 -> Кассир | C30: =Январь!$C$30+RANDBETWEEN(-5000,5000) -> 30772 | D30: =RANDBETWEEN(1000,10000) -> 1696 | E30: =C30+D30 -> 32468
A31: =Январь!$A$31 -> Андреева Вероника Дмитриевна | B31: =Январь!$B$31 -> Управляющий | C31: =Январь!$C$31+RANDBETWEEN(-5000,5000) -> 54702 | D31: =RANDBETWEEN(1000,10000) -> 3353 | E31: =C31+D31 -> 58055

Sheet Июнь
A1: ФИО | B1: Должность | C1: Оклад | D1: Премия | E1: Итого
A2: =Январь!$A$2 -> Иванов Алексей Петрович | B2: =Январь!$B$2 -> Бариста | C2: =Январь!$C$2+RANDBETWEEN(-5000,5000) -> 32479 | D2: =RANDBETWEEN(1000,10000) -> 1847 | E2: =C2+D2 -> 34326
A3: =Январь!$A$3 -> Смирнова Елена Викторовна | B3: =Январь!$B$3 -> Уборщик | C3: =Январь!$C$3+RANDBETWEEN(-5000,5000) -> 24540 | D3: =RANDBETWEEN(1000,10000) -> 3966 | E3: =C3+D3 -> 28506
A4: =Январь!$A$4 -> Кузнецов Дмитрий Сергеевич | B4: =Январь!$B$4 -> Управляющий | C4: =Январь!$C$4+RANDBETWEEN(-5000,5000) -> 51714 | D4: =RANDBETWEEN(1000,10000) -> 8209 | E4: =C4+D4 -> 59923
A5: =Январь!$A$5 -> Попова Анна Игоревна | B5: =Январь!$B$5 -> Бариста | C5: =Январь!$C$5+RANDBETWEEN(-5000,5000) -> 36271 | D5: =RANDBETWEEN(1000,10000) -> 5891 | E5: =C5+D5 -> 42162
A6: =Январь!$A$6 -> Соколов Максим Андреевич | B6: =Январь!$B$6 -> Кондитер | C6: =Январь!$C$6+RANDBETWEEN(-5000,5000) -> 33710 | D6: =RANDBETWEEN(1000,10000) -> 2502 | E6: =C6+D6 -> 36212
A7: =Январь!$A$7 -> Лебедева Ольга Николаевна | B7: =Январь!$B$7 -> Управляющий | C7: =Январь!$C$7+RANDBETWEEN(-5000,5000) -> 53838 | D7: =RANDBETWEEN(1000,10000) -> 5270 | E7: =C7+D7 -> 59108
A8: =Январь!$A$8 -> Козлов Артём Романович | B8: =Январь!$B$8 -> Кондитер | C8: =Январь!$C$8+RANDBETWEEN(-5000,5000) -> 42134 | D8: =RANDBETWEEN(1000,10000) -> 8229 | E8: =C8+D8 -> 50363
A9: =Январь!$A$9 -> Новикова Мария Олеговна | B9: =Январь!$B$9 -> Управляющий | C9: =Январь!$C$9+RANDBETWEEN(-5000,5000) -> 51668 | D9: =RANDBETWEEN(1000,10000) -> 1223 | E9: =C9+D9 -> 52891
A10: =Январь!$A$10 -> Морозов Илья Денисович | B10: =Январь!$B$10 -> Кондитер | C10: =Январь!$C$10+RANDBETWEEN(-5000,5000) -> 37436 | D10: =RANDBETWEEN(1000,10000) -> 3951 | E10: =C10+D10 -> 41387
A11: =Январь!$A$11 -> Петрова Татьяна Юрьевна | B11: =Январь!$B$11 -> Кассир | C11: =Январь!$C$11+RANDBETWEEN(-5000,5000) -> 34295 | D11: =RANDBETWEEN(1000,10000) -> 4615 | E11: =C11+D11 -> 38910
A12: =Январь!$A$12 -> Волков Никита Александрович | B12: =Январь!$B$12 -> Управляющий | C12: =Январь!$C$12+RANDBETWEEN(-5000,5000) -> 58191 | D12: =RANDBETWEEN(1000,10000) -> 5804 | E12: =C12+D12 -> 63995
A13: =Январь!$A$13 -> Соловьёва Дарья Павловна | B13: =Январь!$B$13 -> Бариста | C13: =Январь!$C$13+RANDBETWEEN(-5000,5000) -> 36170 | D13: =RANDBETWEEN(1000,10000) -> 8623 | E13: =C13+D13 -> 44793
A14: =Январь!$A$14 -> Васильев Кирилл Евгеньевич | B14: =Январь!$B$14 -> Управляющий | C14: =Январь!$C$14+RANDBETWEEN(-5000,5000) -> 52155 | D14: =RANDBETWEEN(1000,10000) -> 9367 | E14: =C14+D14 -> 61522
A15: =Январь!$A$15 -> Зайцева Ирина Михайловна | B15: =Январь!$B$15 -> Кассир | C15: =Январь!$C$15+RANDBETWEEN(-5000,5000) -> 31589 | D15: =RANDBETWEEN(1000,10000) -> 2900 | E15: =C15+D15 -> 34489
A16: =Январь!$A$16 -> Павлов Егор Владимирович | B16: =Январь!$B$16 -> Уборщик | C16: =Январь!$C$16+RANDBETWEEN(-5000,5000) -> 29332 | D16: =RANDBETWEEN(1000,10000) -> 2859 | E16: =C16+D16 -> 32191
A17: =Январь!$A$17 -> Семёнова Алина Артёмовна | B17: =Январь!$B$17 -> Кассир | C17: =Январь!$C$17+RANDBETWEEN(-5000,5000) -> 29813 | D17: =RANDBETWEEN(1000,10000) -> 4995 | E17: =C17+D17 -> 34808
A18: =Январь!$A$18 -> Голубев Роман Игоревич | B18: =Январь!$B$18 -> Бариста | C18: =Январь!$C$18+RANDBETWEEN(-5000,5000) -> 30892 | D18: =RANDBETWEEN(1000,10000) -> 7441 | E18: =C18+D18 -> 38333
A19: =Январь!$A$19 -> Виноградова Юлия Сергеевна | B19: =Январь!$B$19 -> Управляющий | C19: =Январь!$C$19+RANDBETWEEN(-5000,5000) -> 57465 | D19: =RANDBETWEEN(1000,10000) -> 4408 | E19: =C19+D19 -> 61873
A20: =Январь!$A$20 -> Богданов Станислав Олегович | B20: =Январь!$B$20 -> Бариста | C20: =Январь!$C$20+RANDBETWEEN(-5000,5000) -> 35824 | D20: =RANDBETWEEN(1000,10000) -> 2196 | E20: =C20+D20 -> 38020
A21: =Январь!$A$21 -> Воробьёва Екатерина Андреевна | B21: =Январь!$B$21 -> Кондитер | C21: =Январь!$C$21+RANDBETWEEN(-5000,5000) -> 37255 | D21: =RANDBETWEEN(1000,10000) -> 3429 | E21: =C21+D21 -> 40684
A22: =Январь!$A$22 -> Фёдоров Павел Дмитриевич | B22: =Январь!$B$22 -> Кондитер | C22: =Январь!$C$22+RANDBETWEEN(-5000,5000) -> 41022 | D22: =RANDBETWEEN(1000,10000) -> 8340 | E22: =C22+D22 -> 49362
A23: =Январь!$A$23 -> Михайлова Светлана Ивановна | B23: =Январь!$B$23 -> Кассир | C23: =Январь!$C$23+RANDBETWEEN(-5000,5000) -> 27978 | D23: =RANDBETWEEN(1000,10000) -> 5169 | E23: =C23+D23 -> 33147
A24: =Январь!$A$24 -> Беляев Антон Николаевич | B24: =Январь!$B$24 -> Управляющий | C24: =Январь!$C$24+RANDBETWEEN(-5000,5000) -> 55570 | D24: =RANDBETWEEN(1000,10000) -> 3670 | E24: =C24+D24 -> 59240
A25: =Январь!$A$25 -> Тарасова Валерия Романовна | B25: =Январь!$B$25 -> Кондитер | C25: =Январь!$C$25+RANDBETWEEN(-5000,5000) -> 41000 | D25: =RANDBETWEEN(1000,10000) -> 8760 | E25: =C25+D25 -> 49760
A26: =Январь!$A$26 -> Белов Глеб Максимович | B26: =Январь!$B$26 -> Бариста | C26: =Январь!$C$26+RANDBETWEEN(-5000,5000) -> 36727 | D26: =RANDBETWEEN(1000,10000) -> 6143 | E26: =C26+D26 -> 42870
A27: =Январь!$A$27 -> Комарова Полина Алексеевна | B27: =Январь!$B$27 -> Кассир | C27: =Январь!$C$27+RANDBETWEEN(-5000,5000) -> 25155 | D27: =RANDBETWEEN(1000,10000) -> 1801 | E27: =C27+D27 -> 26956
A28: =Январь!$A$28 -> Орлов Владислав Станиславович | B28: =Январь!$B$28 -> Управляющий | C28: =Январь!$C$28+RANDBETWEEN(-5000,5000) -> 54296 | D28: =RANDBETWEEN(1000,10000) -> 2922 | E28: =C28+D28 -> 57218
A29: =Январь!$A$29 -> Киселёва Надежда Петровна | B29: =Январь!$B$29 -> Уборщик | C29: =Январь!$C$29+RANDBETWEEN(-5000,5000) -> 20583 | D29: =RANDBETWEEN(1000,10000) -> 4414 | E29: =C29+D29 -> 24997
A30: =Январь!$A$30 -> Макаров Тимур Русланович | B30: =Январь!$B$30 -> Кассир | C30: =Январь!$C$30+RANDBETWEEN(-5000,5000) -> 29409 | D30: =RANDBETWEEN(1000,10000) -> 9978 | E30: =C30+D30 -> 39387
A31: =Январь!$A$31 -> Андреева Вероника Дмитриевна | B31: =Январь!$B$31 -> Управляющий | C31: =Январь!$C$31+RANDBETWEEN(-5000,5000) -> 52825 | D31: =RANDBETWEEN(1000,10000) -> 2981 | E31: =C31+D31 -> 55806

Sheet Июль
A1: ФИО | B1: Должность | C1: Оклад | D1: Премия | E1: Итого
A2: =Январь!$A$2 -> Иванов Алексей Петрович | B2: =Январь!$B$2 -> Бариста | C2: =Январь!$C$2+RANDBETWEEN(-5000,5000) -> 30244 | D2: =RANDBETWEEN(1000,10000) -> 9170 | E2: =C2+D2 -> 39414
A3: =Январь!$A$3 -> Смирнова Елена Викторовна | B3: =Январь!$B$3 -> Уборщик | C3: =Январь!$C$3+RANDBETWEEN(-5000,5000) -> 22075 | D3: =RANDBETWEEN(1000,10000) -> 5667 | E3: =C3+D3 -> 27742
A4: =Январь!$A$4 -> Кузнецов Дмитрий Сергеевич | B4: =Январь!$B$4 -> Управляющий | C4: =Январь!$C$4+RANDBETWEEN(-5000,5000) -> 53313 | D4: =RANDBETWEEN(1000,10000) -> 1459 | E4: =C4+D4 -> 54772
A5: =Январь!$A$5 -> Попова Анна Игоревна | B5: =Январь!$B$5 -> Бариста | C5: =Январь!$C$5+RANDBETWEEN(-5000,5000) -> 36014 | D5: =RANDBETWEEN(1000,10000) -> 1030 | E5: =C5+D5 -> 37044
A6: =Январь!$A$6 -> Соколов Максим Андреевич | B6: =Январь!$B$6 -> Кондитер | C6: =Январь!$C$6+RANDBETWEEN(-5000,5000) -> 41832 | D6: =RANDBETWEEN(1000,10000) -> 3451 | E6: =C6+D6 -> 45283
A7: =Январь!$A$7 -> Лебедева Ольга Николаевна | B7: =Январь!$B$7 -> Управляющий | C7: =Январь!$C$7+RANDBETWEEN(-5000,5000) -> 59045 | D7: =RANDBETWEEN(1000,10000) -> 2408 | E7: =C7+D7 -> 61453
A8: =Январь!$A$8 -> Козлов Артём Романович | B8: =Январь!$B$8 -> Кондитер | C8: =Январь!$C$8+RANDBETWEEN(-5000,5000) -> 37013 | D8: =RANDBETWEEN(1000,10000) -> 4989 | E8: =C8+D8 -> 42002
A9: =Январь!$A$9 -> Новикова Мария Олеговна | B9: =Январь!$B$9 -> Управляющий | C9: =Январь!$C$9+RANDBETWEEN(-5000,5000) -> 59752 | D9: =RANDBETWEEN(1000,10000) -> 8861 | E9: =C9+D9 -> 68613
A10: =Январь!$A$10 -> Морозов Илья Денисович | B10: =Январь!$B$10 -> Кондитер | C10: =Январь!$C$10+RANDBETWEEN(-5000,5000) -> 38457 | D10: =RANDBETWEEN(1000,10000) -> 1580 | E10: =C10+D10 -> 40037
A11: =Январь!$A$11 -> Петрова Татьяна Юрьевна | B11: =Январь!$B$11 -> Кассир | C11: =Январь!$C$11+RANDBETWEEN(-5000,5000) -> 31159 | D11: =RANDBETWEEN(1000,10000) -> 4342 | E11: =C11+D11 -> 35501
A12: =Январь!$A$12 -> Волков Никита Александрович | B12: =Январь!$B$12 -> Управляющий | C12: =Январь!$C$12+RANDBETWEEN(-5000,5000) -> 54025 | D12: =RANDBETWEEN(1000,10000) -> 4307 | E12: =C12+D12 -> 58332
A13: =Январь!$A$13 -> Соловьёва Дарья Павловна | B13: =Январь!$B$13 -> Бариста | C13: =Январь!$C$13+RANDBETWEEN(-5000,5000) -> 37814 | D13: =RANDBETWEEN(1000,10000) -> 6960 | E13: =C13+D13 -> 44774
A14: =Январь!$A$14 -> Васильев Кирилл Евгеньевич | B14: =Январь!$B$14 -> Управляющий | C14: =Январь!$C$14+RANDBETWEEN(-5000,5000) -> 57554 | D14: =RANDBETWEEN(1000,10000) -> 2649 | E14: =C14+D14 -> 60203
A15: =Январь!$A$15 -> Зайцева Ирина Михайловна | B15: =Январь!$B$15 -> Кассир | C15: =Январь!$C$15+RANDBETWEEN(-5000,5000) -> 25492 | D15: =RANDBETWEEN(1000,10000) -> 3624 | E15: =C15+D15 -> 29116
A16: =Январь!$A$16 -> Павлов Егор Владимирович | B16: =Январь!$B$16 -> Уборщик | C16: =Январь!$C$16+RANDBETWEEN(-5000,5000) -> 26506 | D16: =RANDBETWEEN(1000,10000) -> 2565 | E16: =C16+D16 -> 29071
A17: =Январь!$A$17 -> Семёнова Алина Артёмовна | B17: =Январь!$B$17 -> Кассир | C17: =Январь!$C$17+RANDBETWEEN(-5000,5000) -> 27043 | D17: =RANDBETWEEN(1000,10000) -> 8840 | E17: =C17+D17 -> 35883
A18: =Январь!$A$18 -> Голубев Роман Игоревич | B18: =Январь!$B$18 -> Бариста | C18: =Январь!$C$18+RANDBETWEEN(-5000,5000) -> 38442 | D18: =RANDBETWEEN(1000,10000) -> 9170 | E18: =C18+D18 -> 47612
A19: =Январь!$A$19 -> Виноградова Юлия Сергеевна | B19: =Январь!$B$19 -> Управляющий | C19: =Январь!$C$19+RANDBETWEEN(-5000,5000) -> 54155 | D19: =RANDBETWEEN(1000,10000) -> 7486 | E19: =C19+D19 -> 61641
A20: =Январь!$A$20 -> Богданов Станислав Олегович | B20: =Январь!$B$20 -> Бариста | C20: =Январь!$C$20+RANDBETWEEN(-5000,5000) -> 39218 | D20: =RANDBETWEEN(1000,10000) -> 1056 | E20: =C20+D20 -> 40274
A21: =Январь!$A$21 -> Воробьёва Екатерина Андреевна | B21: =Январь!$B$21 -> Кондитер | C21: =Январь!$C$21+RANDBETWEEN(-5000,5000) -> 38122 | D21: =RANDBETWEEN(1000,10000) -> 1900 | E21: =C21+D21 -> 40022
A22: =Январь!$A$22 -> Фёдоров Павел Дмитриевич | B22: =Январь!$B$22 -> Кондитер | C22: =Январь!$C$22+RANDBETWEEN(-5000,5000) -> 38068 | D22: =RANDBETWEEN(1000,10000) -> 5439 | E22: =C22+D22 -> 43507
A23: =Январь!$A$23 -> Михайлова Светлана Ивановна | B23: =Январь!$B$23 -> Кассир | C23: =Январь!$C$23+RANDBETWEEN(-5000,5000) -> 29282 | D23: =RANDBETWEEN(1000,10000) -> 9643 | E23: =C23+D23 -> 38925
A24: =Январь!$A$24 -> Беляев Антон Николаевич | B24: =Январь!$B$24 -> Управляющий | C24: =Январь!$C$24+RANDBETWEEN(-5000,5000) -> 58727 | D24: =RANDBETWEEN(1000,10000) -> 1790 | E24: =C24+D24 -> 60517
A25: =Январь!$A$25 -> Тарасова Валерия Романовна | B25: =Январь!$B$25 -> Кондитер | C25: =Январь!$C$25+RANDBETWEEN(-5000,5000) -> 36901 | D25: =RANDBETWEEN(1000,10000) -> 9453 | E25: =C25+D25 -> 46354
A26: =Январь!$A$26 -> Белов Глеб Максимович | B26: =Январь!$B$26 -> Бариста | C26: =Январь!$C$26+RANDBETWEEN(-5000,5000) -> 37898 | D26: =RANDBETWEEN(1000,10000) -> 9116 | E26: =C26+D26 -> 47014
A27: =Январь!$A$27 -> Комарова Полина Алексеевна | B27: =Январь!$B$27 -> Кассир | C27: =Январь!$C$27+RANDBETWEEN(-5000,5000) -> 31455 | D27: =RANDBETWEEN(1000,10000) -> 4257 | E27: =C27+D27 -> 35712
A28: =Январь!$A$28 -> Орлов Владислав Станиславович | B28: =Январь!$B$28 -> Управляющий | C28: =Январь!$C$28+RANDBETWEEN(-5000,5000) -> 53404 | D28: =RANDBETWEEN(1000,10000) -> 7780 | E28: =C28+D28 -> 61184
A29: =Январь!$A$29 -> Киселёва Надежда Петровна | B29: =Январь!$B$29 -> Уборщик | C29: =Январь!$C$29+RANDBETWEEN(-5000,5000) -> 25828 | D29: =RANDBETWEEN(1000,10000) -> 6234 | E29: =C29+D29 -> 32062
A30: =Январь!$A$30 -> Макаров Тимур Русланович | B30: =Январь!$B$30 -> Кассир | C30: =Январь!$C$30+RANDBETWEEN(-5000,5000) -> 27455 | D30: =RANDBETWEEN(1000,10000) -> 4063 | E30: =C30+D30 -> 31518
A31: =Январь!$A$31 -> Андреева Вероника Дмитриевна | B31: =Январь!$B$31 -> Управляющий | C31: =Январь!$C$31+RANDBETWEEN(-5000,5000) -> 50628 | D31: =RANDBETWEEN(1000,10000) -> 2740 | E31: =C31+D31 -> 53368

Sheet Август
A1: ФИО | B1: Должность | C1: Оклад | D1: Премия | E1: Итого
A2: =Январь!$A$2 -> Иванов Алексей Петрович | B2: =Январь!$B$2 -> Бариста | C2: =Январь!$C$2+RANDBETWEEN(-5000,5000) -> 35649 | D2: =RANDBETWEEN(1000,10000) -> 7882 | E2: =C2+D2 -> 43531
A3: =Январь!$A$3 -> Смирнова Елена Викторовна | B3: =Январь!$B$3 -> Уборщик | C3: =Январь!$C$3+RANDBETWEEN(-5000,5000) -> 22375 | D3: =RANDBETWEEN(1000,10000) -> 7377 | E3: =C3+D3 -> 29752
A4: =Январь!$A$4 -> Кузнецов Дмитрий Сергеевич | B4: =Январь!$B$4 -> Управляющий | C4: =Январь!$C$4+RANDBETWEEN(-5000,5000) -> 58438 | D4: =RANDBETWEEN(1000,10000) -> 9990 | E4: =C4+D4 -> 68428
A5: =Январь!$A$5 -> Попова Анна Игоревна | B5: =Январь!$B$5 -> Бариста | C5: =Январь!$C$5+RANDBETWEEN(-5000,5000) -> 35473 | D5: =RANDBETWEEN(1000,10000) -> 2817 | E5: =C5+D5 -> 38290
A6: =Январь!$A$6 -> Соколов Максим Андреевич | B6: =Январь!$B$6 -> Кондитер | C6: =Январь!$C$6+RANDBETWEEN(-5000,5000) -> 33242 | D6: =RANDBETWEEN(1000,10000) -> 3443 | E6: =C6+D6 -> 36685
A7: =Январь!$A$7 -> Лебедева Ольга Николаевна | B7: =Январь!$B$7 -> Управляющий | C7: =Январь!$C$7+RANDBETWEEN(-5000,5000) -> 50619 | D7: =RANDBETWEEN(1000,10000) -> 6792 | E7: =C7+D7 -> 57411
A8: =Январь!$A$8 -> Козлов Артём Романович | B8: =Январь!$B$8 -> Кондитер | C8: =Январь!$C$8+RANDBETWEEN(-5000,5000) -> 36314 | D8: =RANDBETWEEN(1000,10000) -> 3552 | E8: =C8+D8 -> 39866
A9: =Январь!$A$9 -> Новикова Мария Олеговна | B9: =Январь!$B$9 -> Управляющий | C9: =Январь!$C$9+RANDBETWEEN(-5000,5000) -> 53969 | D9: =RANDBETWEEN(1000,10000) -> 1043 | E9: =C9+D9 -> 55012
A10: =Январь!$A$10 -> Морозов Илья Денисович | B10: =Январь!$B$10 -> Кондитер | C10: =Январь!$C$10+RANDBETWEEN(-5000,5000) -> 42633 | D10: =RANDBETWEEN(1000,10000) -> 9373 | E10: =C10+D10 -> 52006
A11: =Январь!$A$11 -> Петрова Татьяна Юрьевна | B11: =Январь!$B$11 -> Кассир | C11: =Январь!$C$11+RANDBETWEEN(-5000,5000) -> 27047 | D11: =RANDBETWEEN(1000,10000) -> 4111 | E11: =C11+D11 -> 31158
A12: =Январь!$A$12 -> Волков Никита Александрович | B12: =Январь!$B$12 -> Управляющий | C12: =Январь!$C$12+RANDBETWEEN(-5000,5000) -> 50502 | D12: =RANDBETWEEN(1000,10000) -> 6492 | E12: =C12+D12 -> 56994
A13: =Январь!$A$13 -> Соловьёва Дарья Павловна | B13: =Январь!$B$13 -> Бариста | C13: =Январь!$C$13+RANDBETWEEN(-5000,5000) -> 30392 | D13: =RANDBETWEEN(1000,10000) -> 3642 | E13: =C13+D13 -> 34034
A14: =Январь!$A$14 -> Васильев Кирилл Евгеньевич | B14: =Январь!$B$14 -> Управляющий | C14: =Январь!$C$14+RANDBETWEEN(-5000,5000) -> 51395 | D14: =RANDBETWEEN(1000,10000) -> 5192 | E14: =C14+D14 -> 56587
A15: =Январь!$A$15 -> Зайцева Ирина Михайловна | B15: =Январь!$B$15 -> Кассир | C15: =Январь!$C$15+RANDBETWEEN(-5000,5000) -> 26097 | D15: =RANDBETWEEN(1000,10000) -> 5294 | E15: =C15+D15 -> 31391
A16: =Январь!$A$16 -> Павлов Егор Владимирович | B16: =Январь!$B$16 -> Уборщик | C16: =Январь!$C$16+RANDBETWEEN(-5000,5000) -> 29441 | D16: =RANDBETWEEN(1000,10000) -> 6364 | E16: =C16+D16 -> 35805
A17: =Январь!$A$17 -> Семёнова Алина Артёмовна | B17: =Январь!$B$17 -> Кассир | C17: =Январь!$C$17+RANDBETWEEN(-5000,5000) -> 31346 | D17: =RANDBETWEEN(1000,10000) -> 6035 | E17: =C17+D17 -> 37381
A18: =Январь!$A$18 -> Голубев Роман Игоревич | B18: =Январь!$B$18 -> Бариста | C18: =Январь!$C$18+RANDBETWEEN(-5000,5000) -> 30758 | D18: =RANDBETWEEN(1000,10000) -> 9428 | E18: =C18+D18 -> 40186
A19: =Январь!$A$19 -> Виноградова Юлия Сергеевна | B19: =Январь!$B$19 -> Управляющий | C19: =Январь!$C$19+RANDBETWEEN(-5000,5000) -> 50076 | D19: =RANDBETWEEN(1000,10000) -> 5590 | E19: =C19+D19 -> 55666
A20: =Январь!$A$20 -> Богданов Станислав Олегович | B20: =Январь!$B$20 -> Бариста | C20: =Январь!$C$20+RANDBETWEEN(-5000,5000) -> 36566 | D20: =RANDBETWEEN(1000,10000) -> 1959 | E20: =C20+D20 -> 38525
A21: =Январь!$A$21 -> Воробьёва Екатерина Андреевна | B21: =Январь!$B$21 -> Кондитер | C21: =Январь!$C$21+RANDBETWEEN(-5000,5000) -> 35312 | D21: =RANDBETWEEN(1000,10000) -> 5480 | E21: =C21+D21 -> 40792
A22: =Январь!$A$22 -> Фёдоров Павел Дмитриевич | B22: =Январь!$B$22 -> Кондитер | C22: =Январь!$C$22+RANDBETWEEN(-5000,5000) -> 36264 | D22: =RANDBETWEEN(1000,10000) -> 2407 | E22: =C22+D22 -> 38671
A23: =Январь!$A$23 -> Михайлова Светлана Ивановна | B23: =Январь!$B$23 -> Кассир | C23: =Январь!$C$23+RANDBETWEEN(-5000,5000) -> 30185 | D23: =RANDBETWEEN(1000,10000) -> 6166 | E23: =C23+D23 -> 36351
A24: =Январь!$A$24 -> Беляев Антон Николаевич | B24: =Январь!$B$24 -> Управляющий | C24: =Январь!$C$24+RANDBETWEEN(-5000,5000) -> 59105 | D24: =RANDBETWEEN(1000,10000) -> 5757 | E24: =C24+D24 -> 64862
A25: =Январь!$A$25 -> Тарасова Валерия Романовна | B25: =Январь!$B$25 -> Кондитер | C25: =Январь!$C$25+RANDBETWEEN(-5000,5000) -> 39348 | D25: =RANDBETWEEN(1000,10000) -> 7547 | E25: =C25+D25 -> 46895
A26: =Январь!$A$26 -> Белов Глеб Максимович | B26: =Январь!$B$26 -> Бариста | C26: =Январь!$C$26+RANDBETWEEN(-5000,5000) -> 30719 | D26: =RANDBETWEEN(1000,10000) -> 7036 | E26: =C26+D26 -> 37755
A27: =Январь!$A$27 -> Комарова Полина Алексеевна | B27: =Январь!$B$27 -> Кассир | C27: =Январь!$C$27+RANDBETWEEN(-5000,5000) -> 26413 | D27: =RANDBETWEEN(1000,10000) -> 7304 | E27: =C27+D27 -> 33717
A28: =Январь!$A$28 -> Орлов Владислав Станиславович | B28: =Январь!$B$28 -> Управляющий | C28: =Январь!$C$28+RANDBETWEEN(-5000,5000) -> 56272 | D28: =RANDBETWEEN(1000,10000) -> 6376 | E28: =C28+D28 -> 62648
A29: =Январь!$A$29 -> Киселёва Надежда Петровна | B29: =Январь!$B$29 -> Уборщик | C29: =Январь!$C$29+RANDBETWEEN(-5000,5000) -> 21384 | D29: =RANDBETWEEN(1000,10000) -> 8518 | E29: =C29+D29 -> 29902
A30: =Январь!$A$30 -> Макаров Тимур Русланович | B30: =Январь!$B$30 -> Кассир | C30: =Январь!$C$30+RANDBETWEEN(-5000,5000) -> 26178 | D30: =RANDBETWEEN(1000,10000) -> 9528 | E30: =C30+D30 -> 35706
A31: =Январь!$A$31 -> Андреева Вероника Дмитриевна | B31: =Январь!$B$31 -> Управляющий | C31: =Январь!$C$31+RANDBETWEEN(-5000,5000) -> 59745 | D31: =RANDBETWEEN(1000,10000) -> 2907 | E31: =C31+D31 -> 62652

Sheet Сентябрь
A1: ФИО | B1: Должность | C1: Оклад | D1: Премия | E1: Итого
A2: =Январь!$A$2 -> Иванов Алексей Петрович | B2: =Январь!$B$2 -> Бариста | C2: =Январь!$C$2+RANDBETWEEN(-5000,5000) -> 34096 | D2: =RANDBETWEEN(1000,10000) -> 9147 | E2: =C2+D2 -> 43243
A3: =Январь!$A$3 -> Смирнова Елена Викторовна | B3: =Январь!$B$3 -> Уборщик | C3: =Январь!$C$3+RANDBETWEEN(-5000,5000) -> 22847 | D3: =RANDBETWEEN(1000,10000) -> 8609 | E3: =C3+D3 -> 31456
A4: =Январь!$A$4 -> Кузнецов Дмитрий Сергеевич | B4: =Январь!$B$4 -> Управляющий | C4: =Январь!$C$4+RANDBETWEEN(-5000,5000) -> 54358 | D4: =RANDBETWEEN(1000,10000) -> 7887 | E4: =C4+D4 -> 62245
A5: =Январь!$A$5 -> Попова Анна Игоревна | B5: =Январь!$B$5 -> Бариста | C5: =Январь!$C$5+RANDBETWEEN(-5000,5000) -> 36240 | D5: =RANDBETWEEN(1000,10000) -> 2595 | E5: =C5+D5 -> 38835
A6: =Январь!$A$6 -> Соколов Максим Андреевич | B6: =Январь!$B$6 -> Кондитер | C6: =Январь!$C$6+RANDBETWEEN(-5000,5000) -> 37883 | D6: =RANDBETWEEN(1000,10000) -> 4798 | E6: =C6+D6 -> 42681
A7: =Январь!$A$7 -> Лебедева Ольга Николаевна | B7: =Январь!$B$7 -> Управляющий | C7: =Январь!$C$7+RANDBETWEEN(-5000,5000) -> 51071 | D7: =RANDBETWEEN(1000,10000) -> 8435 | E7: =C7+D7 -> 59506
A8: =Январь!$A$8 -> Козлов Артём Романович | B8: =Январь!$B$8 -> Кондитер | C8: =Январь!$C$8+RANDBETWEEN(-5000,5000) -> 37010 | D8: =RANDBETWEEN(1000,10000) -> 9055 | E8: =C8+D8 -> 46065
A9: =Январь!$A$9 -> Новикова Мария Олеговна | B9: =Январь!$B$9 -> Управляющий | C9: =Январь!$C$9+RANDBETWEEN(-5000,5000) -> 58353 | D9: =RANDBETWEEN(1000,10000) -> 8022 | E9: =C9+D9 -> 66375
A10: =Январь!$A$10 -> Морозов Илья Денисович | B10: =Январь!$B$10 -> Кондитер | C10: =Январь!$C$10+RANDBETWEEN(-5000,5000) -> 37372 | D10: =RANDBETWEEN(1000,10000) -> 9709 | E10: =C10+D10 -> 47081
A11: =Январь!$A$11 -> Петрова Татьяна Юрьевна | B11: =Январь!$B$11 -> Кассир | C11: =Январь!$C$11+RANDBETWEEN(-5000,5000) -> 27984 | D11: =RANDBETWEEN(1000,10000) -> 5248 | E11: =C11+D11 -> 33232
A12: =Январь!$A$12 -> Волков Никита Александрович | B12: =Январь!$B$12 -> Управляющий | C12: =Январь!$C$12+RANDBETWEEN(-5000,5000) -> 53415 | D12: =RANDBETWEEN(1000,10000) -> 2725 | E12: =C12+D12 -> 56140
A13: =Январь!$A$13 -> Соловьёва Дарья Павловна | B13: =Январь!$B$13 -> Бариста | C13: =Январь!$C$13+RANDBETWEEN(-5000,5000) -> 35393 | D13: =RANDBETWEEN(1000,10000) -> 6668 | E13: =C13+D13 -> 42061
A14: =Январь!$A$14 -> Васильев Кирилл Евгеньевич | B14: =Январь!$B$14 -> Управляющий | C14: =Январь!$C$14+RANDBETWEEN(-5000,5000) -> 57855 | D14: =RANDBETWEEN(1000,10000) -> 3861 | E14: =C14+D14 -> 61716
A15: =Январь!$A$15 -> Зайцева Ирина Михайловна | B15: =Январь!$B$15 -> Кассир | C15: =Январь!$C$15+RANDBETWEEN(-5000,5000) -> 29806 | D15: =RANDBETWEEN(1000,10000) -> 1005 | E15: =C15+D15 -> 30811
A16: =Январь!$A$16 -> Павлов Егор Владимирович | B16: =Январь!$B$16 -> Уборщик | C16: =Январь!$C$16+RANDBETWEEN(-5000,5000) -> 26989 | D16: =RANDBETWEEN(1000,10000) -> 4328 | E16: =C16+D16 -> 31317
A17: =Январь!$A$17 -> Семёнова Алина Артёмовна | B17: =Январь!$B$17 -> Кассир | C17: =Январь!$C$17+RANDBETWEEN(-5000,5000) -> 34055 | D17: =RANDBETWEEN(1000,10000) -> 9286 | E17: =C17+D17 -> 43341
A18: =Январь!$A$18 -> Голубев Роман Игоревич | B18: =Январь!$B$18 -> Бариста | C18: =Январь!$C$18+RANDBETWEEN(-5000,5000) -> 34001 | D18: =RANDBETWEEN(1000,10000) -> 8604 | E18: =C18+D18 -> 42605
A19: =Январь!$A$19 -> Виноградова Юлия Сергеевна | B19: =Январь!$B$19 -> Управляющий | C19: =Январь!$C$19+RANDBETWEEN(-5000,5000) -> 59385 | D19: =RANDBETWEEN(1000,10000) -> 1606 | E19: =C19+D19 -> 60991
A20: =Январь!$A$20 -> Богданов Станислав Олегович | B20: =Январь!$B$20 -> Бариста | C20: =Январь!$C$20+RANDBETWEEN(-5000,5000) -> 35398 | D20: =RANDBETWEEN(1000,10000) -> 7124 | E20: =C20+D20 -> 42522
A21: =Январь!$A$21 -> Воробьёва Екатерина Андреевна | B21: =Январь!$B$21 -> Кондитер | C21: =Январь!$C$21+RANDBETWEEN(-5000,5000) -> 33149 | D21: =RANDBETWEEN(1000,10000) -> 5962 | E21: =C21+D21 -> 39111
A22: =Январь!$A$22 -> Фёдоров Павел Дмитриевич | B22: =Январь!$B$22 -> Кондитер | C22: =Январь!$C$22+RANDBETWEEN(-5000,5000) -> 38970 | D22: =RANDBETWEEN(1000,10000) -> 6083 | E22: =C22+D22 -> 45053
A23: =Январь!$A$23 -> Михайлова Светлана Ивановна | B23: =Январь!$B$23 -> Кассир | C23: =Январь!$C$23+RANDBETWEEN(-5000,5000) -> 25853 | D23: =RANDBETWEEN(1000,10000) -> 1328 | E23: =C23+D23 -> 27181
A24: =Январь!$A$24 -> Беляев Антон Николаевич | B24: =Январь!$B$24 -> Управляющий | C24: =Январь!$C$24+RANDBETWEEN(-5000,5000) -> 56007 | D24: =RANDBETWEEN(1000,10000) -> 9455 | E24: =C24+D24 -> 65462
A25: =Январь!$A$25 -> Тарасова Валерия Романовна | B25: =Январь!$B$25 -> Кондитер | C25: =Январь!$C$25+RANDBETWEEN(-5000,5000) -> 36192 | D25: =RANDBETWEEN(1000,10000) -> 1595 | E25: =C25+D25 -> 37787
A26: =Январь!$A$26 -> Белов Глеб Максимович | B26: =Январь!$B$26 -> Бариста | C26: =Январь!$C$26+RANDBETWEEN(-5000,5000) -> 33299 | D26: =RANDBETWEEN(1000,10000) -> 8604 | E26: =C26+D26 -> 41903
A27: =Январь!$A$27 -> Комарова Полина Алексеевна | B27: =Январь!$B$27 -> Кассир | C27: =Январь!$C$27+RANDBETWEEN(-5000,5000) -> 33412 | D27: =RANDBETWEEN(1000,10000) -> 6235 | E27: =C27+D27 -> 39647
A28: =Январь!$A$28 -> Орлов Владислав Станиславович | B28: =Январь!$B$28 -> Управляющий | C28: =Январь!$C$28+RANDBETWEEN(-5000,5000) -> 54685 | D28: =RANDBETWEEN(1000,10000) -> 4190 | E28: =C28+D28 -> 58875
A29: =Январь!$A$29 -> Киселёва Надежда Петровна | B29: =Январь!$B$29 -> Уборщик | C29: =Январь!$C$29+RANDBETWEEN(-5000,5000) -> 26006 | D29: =RANDBETWEEN(1000,10000) -> 5368 | E29: =C29+D29 -> 31374
A30: =Январь!$A$30 -> Макаров Тимур Русланович | B30: =Январь!$B$30 -> Кассир | C30: =Январь!$C$30+RANDBETWEEN(-5000,5000) -> 30261 | D30: =RANDBETWEEN(1000,10000) -> 2581 | E30: =C30+D30 -> 32842
A31: =Январь!$A$31 -> Андреева Вероника Дмитриевна | B31: =Январь!$B$31 -> Управляющий | C31: =Январь!$C$31+RANDBETWEEN(-5000,5000) -> 59285 | D31: =RANDBETWEEN(1000,10000) -> 9929 | E31: =C31+D31 -> 69214

Sheet Октябрь
A1: ФИО | B1: Должность | C1: Оклад | D1: Премия | E1: Итого
A2: =Январь!$A$2 -> Иванов Алексей Петрович | B2: =Январь!$B$2 -> Бариста | C2: =Январь!$C$2+RANDBETWEEN(-5000,5000) -> 38108 | D2: =RANDBETWEEN(1000,10000) -> 1885 | E2: =C2+D2 -> 39993
A3: =Январь!$A$3 -> Смирнова Елена Викторовна | B3: =Январь!$B$3 -> Уборщик | C3: =Январь!$C$3+RANDBETWEEN(-5000,5000) -> 28954 | D3: =RANDBETWEEN(1000,10000) -> 1270 | E3: =C3+D3 -> 30224
A4: =Январь!$A$4 -> Кузнецов Дмитрий Сергеевич | B4: =Январь!$B$4 -> Управляющий | C4: =Январь!$C$4+RANDBETWEEN(-5000,5000) -> 53626 | D4: =RANDBETWEEN(1000,10000) -> 9023 | E4: =C4+D4 -> 62649
A5: =Январь!$A$5 -> Попова Анна Игоревна | B5: =Январь!$B$5 -> Бариста | C5: =Январь!$C$5+RANDBETWEEN(-5000,5000) -> 37453 | D5: =RANDBETWEEN(1000,10000) -> 5589 | E5: =C5+D5 -> 43042
A6: =Январь!$A$6 -> Соколов Максим Андреевич | B6: =Январь!$B$6 -> Кондитер | C6: =Январь!$C$6+RANDBETWEEN(-5000,5000) -> 38349 | D6: =RANDBETWEEN(1000,10000) -> 1694 | E6: =C6+D6 -> 40043
A7: =Январь!$A$7 -> Лебедева Ольга Николаевна | B7: =Январь!$B$7 -> Управляющий | C7: =Январь!$C$7+RANDBETWEEN(-5000,5000) -> 52773 | D7: =RANDBETWEEN(1000,10000) -> 1751 | E7: =C7+D7 -> 54524
A8: =Январь!$A$8 -> Козлов Артём Романович | B8: =Январь!$B$8 -> Кондитер | C8: =Январь!$C$8+RANDBETWEEN(-5000,5000) -> 36374 | D8: =RANDBETWEEN(1000,10000) -> 7038 | E8: =C8+D8 -> 43412
A9: =Январь!$A$9 -> Новикова Мария Олеговна | B9: =Январь!$B$9 -> Управляющий | C9: =Январь!$C$9+RANDBETWEEN(-5000,5000) -> 59593 | D9: =RANDBETWEEN(1000,10000) -> 7734 | E9: =C9+D9 -> 67327
A10: =Январь!$A$10 -> Морозов Илья Денисович | B10: =Январь!$B$10 -> Кондитер | C10: =Январь!$C$10+RANDBETWEEN(-5000,5000) -> 39815 | D10: =RANDBETWEEN(1000,10000) -> 4671 | E10: =C10+D10 -> 44486
A11: =Январь!$A$11 -> Петрова Татьяна Юрьевна | B11: =Январь!$B$11 -> Кассир | C11: =Январь!$C$11+RANDBETWEEN(-5000,5000) -> 30199 | D11: =RANDBETWEEN(1000,10000) -> 9678 | E11: =C11+D11 -> 39877
A12: =Январь!$A$12 -> Волков Никита Александрович | B12: =Январь!$B$12 -> Управляющий | C12: =Январь!$C$12+RANDBETWEEN(-5000,5000) -> 55443 | D12: =RANDBETWEEN(1000,10000) -> 4024 | E12: =C12+D12 -> 59467
A13: =Январь!$A$13 -> Соловьёва Дарья Павловна | B13: =Январь!$B$13 -> Бариста | C13: =Январь!$C$13+RANDBETWEEN(-5000,5000) -> 39628 | D13: =RANDBETWEEN(1000,10000) -> 6041 | E13: =C13+D13 -> 45669
A14: =Январь!$A$14 -> Васильев Кирилл Евгеньевич | B14: =Январь!$B$14 -> Управляющий | C14: =Январь!$C$14+RANDBETWEEN(-5000,5000) -> 54592 | D14: =RANDBETWEEN(1000,10000) -> 3019 | E14: =C14+D14 -> 57611
A15: =Январь!$A$15 -> Зайцева Ирина Михайловна | B15: =Январь!$B$15 -> Кассир | C15: =Январь!$C$15+RANDBETWEEN(-5000,5000) -> 26450 | D15: =RANDBETWEEN(1000,10000) -> 9002 | E15: =C15+D15 -> 35452
A16: =Январь!$A$16 -> Павлов Егор Владимирович | B16: =Январь!$B$16 -> Уборщик | C16: =Январь!$C$16+RANDBETWEEN(-5000,5000) -> 20831 | D16: =RANDBETWEEN(1000,10000) -> 9273 | E16: =C16+D16 -> 30104
A17: =Январь!$A$17 -> Семёнова Алина Артёмовна | B17: =Январь!$B$17 -> Кассир | C17: =Январь!$C$17+RANDBETWEEN(-5000,5000) -> 28282 | D17: =RANDBETWEEN(1000,10000) -> 3462 | E17: =C17+D17 -> 31744
A18: =Январь!$A$18 -> Голубев Роман Игоревич | B18: =Январь!$B$18 -> Бариста | C18: =Январь!$C$18+RANDBETWEEN(-5000,5000) -> 36982 | D18: =RANDBETWEEN(1000,10000) -> 3668 | E18: =C18+D18 -> 40650
A19: =Январь!$A$19 -> Виноградова Юлия Сергеевна | B19: =Январь!$B$19 -> Управляющий | C19: =Январь!$C$19+RANDBETWEEN(-5000,5000) -> 50445 | D19: =RANDBETWEEN(1000,10000) -> 4668 | E19: =C19+D19 -> 55113
A20: =Январь!$A$20 -> Богданов Станислав Олегович | B20: =Январь!$B$20 -> Бариста | C20: =Январь!$C$20+RANDBETWEEN(-5000,5000) -> 31205 | D20: =RANDBETWEEN(1000,10000) -> 8822 | E20: =C20+D20 -> 40027
A21: =Январь!$A$21 -> Воробьёва Екатерина Андреевна | B21: =Январь!$B$21 -> Кондитер | C21: =Январь!$C$21+RANDBETWEEN(-5000,5000) -> 39804 | D21: =RANDBETWEEN(1000,10000) -> 6609 | E21: =C21+D21 -> 46413
A22: =Январь!$A$22 -> Фёдоров Павел Дмитриевич | B22: =Январь!$B$22 -> Кондитер | C22: =Январь!$C$22+RANDBETWEEN(-5000,5000) -> 41596 | D22: =RANDBETWEEN(1000,10000) -> 3603 | E22: =C22+D22 -> 45199
A23: =Январь!$A$23 -> Михайлова Светлана Ивановна | B23: =Январь!$B$23 -> Кассир | C23: =Январь!$C$23+RANDBETWEEN(-5000,5000) -> 33191 | D23: =RANDBETWEEN(1000,10000) -> 9131 | E23: =C23+D23 -> 42322
A24: =Январь!$A$24 -> Беляев Антон Николаевич | B24: =Январь!$B$24 -> Управляющий | C24: =Январь!$C$24+RANDBETWEEN(-5000,5000) -> 56588 | D24: =RANDBETWEEN(1000,10000) -> 2789 | E24: =C24+D24 -> 59377
A25: =Январь!$A$25 -> Тарасова Валерия Романовна | B25: =Январь!$B$25 -> Кондитер | C25: =Январь!$C$25+RANDBETWEEN(-5000,5000) -> 33957 | D25: =RANDBETWEEN(1000,10000) -> 1026 | E25: =C25+D25 -> 34983
A26: =Январь!$A$26 -> Белов Глеб Максимович | B26: =Январь!$B$26 -> Бариста | C26: =Январь!$C$26+RANDBETWEEN(-5000,5000) -> 32785 | D26: =RANDBETWEEN(1000,10000) -> 1405 | E26: =C26+D26 -> 34190
A27: =Январь!$A$27 -> Комарова Полина Алексеевна | B27: =Январь!$B$27 -> Кассир | C27: =Январь!$C$27+RANDBETWEEN(-5000,5000) -> 34078 | D27: =RANDBETWEEN(1000,10000) -> 7042 | E27: =C27+D27 -> 41120
A28: =Январь!$A$28 -> Орлов Владислав Станиславович | B28: =Январь!$B$28 -> Управляющий | C28: =Январь!$C$28+RANDBETWEEN(-5000,5000) -> 50421 | D28: =RANDBETWEEN(1000,10000) -> 4913 | E28: =C28+D28 -> 55334
A29: =Январь!$A$29 -> Киселёва Надежда Петровна | B29: =Январь!$B$29 -> Уборщик | C29: =Январь!$C$29+RANDBETWEEN(-5000,5000) -> 28449 | D29: =RANDBETWEEN(1000,10000) -> 4978 | E29: =C29+D29 -> 33427
A30: =Январь!$A$30 -> Макаров Тимур Русланович | B30: =Январь!$B$30 -> Кассир | C30: =Январь!$C$30+RANDBETWEEN(-5000,5000) -> 25861 | D30: =RANDBETWEEN(1000,10000) -> 1816 | E30: =C30+D30 -> 27677
A31: =Январь!$A$31 -> Андреева Вероника Дмитриевна | B31: =Январь!$B$31 -> Управляющий | C31: =Январь!$C$31+RANDBETWEEN(-5000,5000) -> 51432 | D31: =RANDBETWEEN(1000,10000) -> 7637 | E31: =C31+D31 -> 59069

Sheet Ноябрь
A1: ФИО | B1: Должность | C1: Оклад | D1: Премия | E1: Итого
A2: =Январь!$A$2 -> Иванов Алексей Петрович | B2: =Январь!$B$2 -> Бариста | C2: =Январь!$C$2+RANDBETWEEN(-5000,5000) -> 33592 | D2: =RANDBETWEEN(1000,10000) -> 2628 | E2: =C2+D2 -> 36220
A3: =Январь!$A$3 -> Смирнова Елена Викторовна | B3: =Январь!$B$3 -> Уборщик | C3: =Январь!$C$3+RANDBETWEEN(-5000,5000) -> 29726 | D3: =RANDBETWEEN(1000,10000) -> 3057 | E3: =C3+D3 -> 32783
A4: =Январь!$A$4 -> Кузнецов Дмитрий Сергеевич | B4: =Январь!$B$4 -> Управляющий | C4: =Январь!$C$4+RANDBETWEEN(-5000,5000) -> 57029 | D4: =RANDBETWEEN(1000,10000) -> 3681 | E4: =C4+D4 -> 60710
A5: =Январь!$A$5 -> Попова Анна Игоревна | B5: =Январь!$B$5 -> Бариста | C5: =Январь!$C$5+RANDBETWEEN(-5000,5000) -> 38265 | D5: =RANDBETWEEN(1000,10000) -> 6045 | E5: =C5+D5 -> 44310
A6: =Январь!$A$6 -> Соколов Максим Андреевич | B6: =Январь!$B$6 -> Кондитер | C6: =Январь!$C$6+RANDBETWEEN(-5000,5000) -> 38381 | D6: =RANDBETWEEN(1000,10000) -> 1341 | E6: =C6+D6 -> 39722
A7: =Январь!$A$7 -> Лебедева Ольга Николаевна | B7: =Январь!$B$7 -> Управляющий | C7: =Январь!$C$7+RANDBETWEEN(-5000,5000) -> 59387 | D7: =RANDBETWEEN(1000,10000) -> 8576 | E7: =C7+D7 -> 67963
A8: =Январь!$A$8 -> Козлов Артём Романович | B8: =Январь!$B$8 -> Кондитер | C8: =Январь!$C$8+RANDBETWEEN(-5000,5000) -> 34527 | D8: =RANDBETWEEN(1000,10000) -> 8929 | E8: =C8+D8 -> 43456
A9: =Январь!$A$9 -> Новикова Мария Олеговна | B9: =Январь!$B$9 -> Управляющий | C9: =Январь!$C$9+RANDBETWEEN(-5000,5000) -> 54022 | D9: =RANDBETWEEN(1000,10000) -> 4871 | E9: =C9+D9 -> 58893
A10: =Январь!$A$10 -> Морозов Илья Денисович | B10: =Январь!$B$10 -> Кондитер | C10: =Январь!$C$10+RANDBETWEEN(-5000,5000) -> 38977 | D10: =RANDBETWEEN(1000,10000) -> 3762 | E10: =C10+D10 -> 42739
A11: =Январь!$A$11 -> Петрова Татьяна Юрьевна | B11: =Январь!$B$11 -> Кассир | C11: =Январь!$C$11+RANDBETWEEN(-5000,5000) -> 27412 | D11: =RANDBETWEEN(1000,10000) -> 3933 | E11: =C11+D11 -> 31345
A12: =Январь!$A$12 -> Волков Никита Александрович | B12: =Январь!$B$12 -> Управляющий | C12: =Январь!$C$12+RANDBETWEEN(-5000,5000) -> 59905 | D12: =RANDBETWEEN(1000,10000) -> 3567 | E12: =C12+D12 -> 63472
